using System;
using System.Console;

   module Program
    {

        Main() : void
        {
            try
            {
              WriteLine("test exception");
              throw ArgumentException();
            }
            catch
            {
              | ArgumentException => WriteLine("Ok")
            }
            try
            {
              WriteLine("test exception2");
            }
            catch
            {
              | argumentException => WriteLine("Fail") // W: N168: a caught exception argumentException was never used \(defined in 'Main\(\) : void'\)
            }
            WriteLine("Ok");
        }
    }


/*
BEGIN-OUTPUT
test exception
Ok
test exception2
Ok
END-OUTPUT
*/
